Workbook

Sheet Deal Overview
A1: INSTITUTIONAL RETAIL UNDERWRITER | DEAL OVERVIEW
A2: German Commercial Real Estate – Investment Committee Template | v1.0
A4: A | PROPERTY IDENTITY
A5: Property Name / Asset | G5: e.g. Stadtgalerie Kaufbeuren
A6: Street Address
A7: City / Bundesland
A8: Asset Type | G8: Shopping Centre / Retail Park / High-Street / Mixed
A9: GLA – Gross Lettable Area (m²) | G9: Total lettable sqm incl. anchor
A10: Year Built / Last Refurb
A11: Number of Tenants | G11: =COUNTA('Rent Roll'!B4:B103) -> 3
A12: Number of Floors
A13: Parking Spaces
A15: B | TRANSACTION PARAMETERS
A16: Asking Price (€) | G16: Purchase price before costs
A17: Equity Investment (€) | G17: Own funds contributed
A18: Senior Loan Amount (€) | G18: =B16-B17 -> 0
A19: LTV at Acquisition (%) | G19: =IFERROR(B18/B16,"-") -> -
A20: GrESt Rate (%) | G20: 3.5%–6.5% depending on Bundesland
A21: Notar & Grundbuch (%) | G21: ~1.5% typical
A22: Broker Fee (%) | G22: ~1%–3%
A23: Total Acquisition Cost (€) | G23: =B16*(1+B20+B21+B22) -> 0
A24: Analysis Date
A25: Target Hold Period (Years) | G25: 10
A27: C | FINANCING STRUCTURE
A28: Interest Rate – Senior (%) | G28: Current market: ~4.1–4.3%
A29: Loan Term (Years) | G29: 10
A30: Amortisation Type | G30: Annuitätendarlehen / Endfällig / IO
A31: Annual Amortisation (%) | G31: 2.0% standard German CRE
A32: Annual Debt Service (€) | G32: =IFERROR(B18*(B28+B31),"-") -> 0
A33: IO Period (Years) | G33: 0–3, enter 0 if none
A35: D | KEY OUTPUT METRICS (auto-calculated from Rent Roll)
A36: KPI | B36: Value | C36: Benchmark | D36: Traffic Light | E36: Notes
A37: Gross Passing Rent (€/yr) | B37: ='Rent Roll'!B110 -> 450240 | C37: —
A38: Net Operating Income (€/yr) | B38: ='Rent Roll'!B112 -> ** Link to Cost Sheet or enter manually ** | C38: — | E38: Passing rent – non-recoverable costs
A39: Gross Initial Yield (%) | B39: =IFERROR(B38/B16,"-") -> - | C39: 5.5%–9% retail DE | E39: NOI / Purchase Price
A40: DSCR | B40: =IFERROR(B38/B32,"-") -> - | C40: >1.30x (bank min) | E40: NOI / Annual Debt Service
A41: ICR | B41: =IFERROR(B38/(B18*B28),"-") -> - | C41: ≥1.75x | E41: NOI / Interest only
A42: LTV at Acquisition (%) | B42: =B19 -> 0 | C42: <65% | E42: Senior loan / Purchase Price
A43: WAULT (Years) | B43: ='Rent Roll'!B115 -> 2.4858868 | C43: >4 yrs | E43: Weighted Avg Unexpired Lease Term
A44: Vacancy Rate (%) | B44: ='Rent Roll'!B117 -> 0.10638298 | C44: <10% | E44: Vacant m² / Total GLA
...

Sheet Rent Roll
A1: RENT ROLL | Institutional Input Sheet – Enter one row per lease unit
A2: Blue cells = your inputs | Black cells = auto-calculated | Max 100 rows (rows 4–103) | Leave vacant units with Tenant = 'VACANT'
A3: Unit Ref | B3: Tenant Name | C3: Trade Sector | D3: Anchor? (Y/N) | E3: Leased Area (m²) | F3: Passing Rent €/m²/mo | G3: Annual Rent (€) | H3: Lease Start | I3: Lease Expiry | J3: Break Option Date | K3: Unexpired Term (Yrs) | L3: CPI Clause (Y/N) | M3: CPI Pass-Through % | N3: CPI Trigger % | O3: Security Deposit (€) | P3: Service Charge Recov. (Y/N) | Q3: Rent-Free Months | R3: Notes / Observations
A4: U-01 | B4: Rewe Markt GmbH | C4: Food & Grocery | D4: Y | E4: 2800 | F4: 8.5 | G4: =IFERROR(E4*F4*12,0) -> 285600 | H4: 43466 | I4: 47483 | K4: =IFERROR(IF(B4="VACANT",0,(I4-TODAY())/365.25),0) -> 3.797399 | L4: Y | M4: 75% | N4: 10% | O4: 50000 | P4: Y | Q4: 0 | R4: Anchor – index clause active
A5: U-02 | B5: H&M Hennes & Mauritz | C5: Fashion | D5: N | E5: 980 | F5: 14 | G5: =IFERROR(E5*F5*12,0) -> 164640 | H5: 44348 | I5: 46173 | J5: 45443 | K5: =IFERROR(IF(B5="VACANT",0,(I5-TODAY())/365.25),0) -> 0.21081451 | L5: Y | M5: 100% | N5: 10% | O5: 25000 | P5: Y | Q5: 3 | R5: Break option June 2024 – NOT exercised
A6: U-03 | B6: VACANT | C6: — | D6: N | E6: 450 | F6: 0 | G6: =IFERROR(E6*F6*12,0) -> 0 | K6: =IFERROR(IF(B6="VACANT",0,(I6-TODAY())/365.25),0) -> 0 | L6: N | M6: 0% | N6: 0% | O6: 0 | P6: N | Q6: 0 | R6: Void since Jan 2025 – actively marketed
G7: =IFERROR(E7*F7*12,0) -> 0 | K7: =IFERROR(IF(B7="VACANT",0,(I7-TODAY())/365.25),0) -> -126.20397
G8: =IFERROR(E8*F8*12,0) -> 0 | K8: =IFERROR(IF(B8="VACANT",0,(I8-TODAY())/365.25),0) -> -126.20397
G9: =IFERROR(E9*F9*12,0) -> 0 | K9: =IFERROR(IF(B9="VACANT",0,(I9-TODAY())/365.25),0) -> -126.20397
G10: =IFERROR(E10*F10*12,0) -> 0 | K10: =IFERROR(IF(B10="VACANT",0,(I10-TODAY())/365.25),0) -> -126.20397
G11: =IFERROR(E11*F11*12,0) -> 0 | K11: =IFERROR(IF(B11="VACANT",0,(I11-TODAY())/365.25),0) -> -126.20397
G12: =IFERROR(E12*F12*12,0) -> 0 | K12: =IFERROR(IF(B12="VACANT",0,(I12-TODAY())/365.25),0) -> -126.20397
G13: =IFERROR(E13*F13*12,0) -> 0 | K13: =IFERROR(IF(B13="VACANT",0,(I13-TODAY())/365.25),0) -> -126.20397
G14: =IFERROR(E14*F14*12,0) -> 0 | K14: =IFERROR(IF(B14="VACANT",0,(I14-TODAY())/365.25),0) -> -126.20397
G15: =IFERROR(E15*F15*12,0) -> 0 | K15: =IFERROR(IF(B15="VACANT",0,(I15-TODAY())/365.25),0) -> -126.20397
G16: =IFERROR(E16*F16*12,0) -> 0 | K16: =IFERROR(IF(B16="VACANT",0,(I16-TODAY())/365.25),0) -> -126.20397
G17: =IFERROR(E17*F17*12,0) -> 0 | K17: =IFERROR(IF(B17="VACANT",0,(I17-TODAY())/365.25),0) -> -126.20397
G18: =IFERROR(E18*F18*12,0) -> 0 | K18: =IFERROR(IF(B18="VACANT",0,(I18-TODAY())/365.25),0) -> -126.20397
... G103: =IFERROR(E103*F103*12,0) -> 0 | K103: =IFERROR(IF(B103="VACANT",0,(I103-TODAY())/365.25),0) -> -126.20397
A106: SUMMARY METRICS (referenced by Deal Overview)
A107: Total Leased Area (m²) | B107: =SUMIF(B4:B103,"<>VACANT",E4:E103) -> 3780
A108: Total Vacant Area (m²) | B108: =SUMIF(B4:B103,"VACANT",E4:E103) -> 450
A109: Total GLA (m²) | B109: =B107+B108 -> 4230
A110: Gross Passing Rent (€/yr) | B110: =SUMIF(B4:B103,"<>VACANT",G4:G103) -> 450240
A111: ERV – Estimated Rental Value | B111: ** Enter manually from market appraisal **
A112: NOI (Passing Rent – Non-Recov.) | B112: ** Link to Cost Sheet or enter manually **
A113: Number of Active Leases | B113: =COUNTIF(B4:B103,"<>VACANT") -> 99
A114: Number of Vacant Units | B114: =COUNTIF(B4:B103,"VACANT") -> 1
A115: WAULT (Years) | B115: =IFERROR(SUMPRODUCT((B4:B103<>"VACANT")*G4:G103*K4:K103)/SUMIF(B4:B103,"<>VACANT",G4:G103),0) -> 2.4858868
A116: Weighted Avg Rent (€/m²/mo) | B116: =IFERROR(B110/(B107*12),0) -> 9.9259259
A117: Vacancy Rate (%) | B117: =IFERROR(B108/B109,0) -> 0.10638298
A118: CPI-Indexed Lease Share (%) | B118: =IFERROR(COUNTIF(L4:L103,"Y")/B113,0) -> 0.02020202
A119: Anchor Concentration (%) | B119: =IFERROR(SUMIF(D4:D103,"Y",G4:G103)/B110,0) -> 0.63432836
A120: Shortest Unexpired Term (Yrs) | B120: =IFERROR(minifs(K4:K103,B4:B103,"<>VACANT"),0) -> 0

Sheet Cost Sheet
A1: COST SHEET | Non-Recoverable Operating Costs — German CRE Standard
A2: Blue = your inputs | Black = auto-calculated | Yellow = priority inputs | All figures annual (€/yr) unless noted
A4: A | INCOME REFERENCE (linked from Rent Roll — do not edit)
A5: Gross Passing Rent (€/yr) | B5: ='Rent Roll'!B110 -> 450240
A6: Total GLA (m²) | B6: ='Rent Roll'!B109 -> 4230
A7: Leased Area (m²) | B7: ='Rent Roll'!B107 -> 3780
A8: Vacant Area (m²) | B8: ='Rent Roll'!B108 -> 450
A9: Vacancy Rate (%) | B9: ='Rent Roll'!B117 -> 0.10638298
A10: Number of Vacant Units | B10: ='Rent Roll'!B114 -> 1
A12: B | NON-RECOVERABLE OPERATING COSTS (Nicht-umlagefähige Kosten)
A13: Cost Item | B13: Basis | C13: Rate / Amount | D13: Annual Cost (€) | E13: Notes
A14: Property Management Fee | B14: % of Gross Rent | C14: 0.015 | D14: =C14*B5 -> 6753.6 | E14: Typical German: 1.0–2.0% of gross rent. Negotiate at acquisition.
A15: Asset Management Fee | B15: % of Gross Rent | C15: 0.005 | D15: =C15*B5 -> 2251.2 | E15: Institutional owners charge 0.3–0.75% internally. External: 0.5–1.0%.
A16: Building Insurance (Gebäudeversicherung) | B16: € per m² GLA / yr | C16: 2.5 | D16: =C16*B6 -> 10575 | E16: Range: €1.50–€4.00/m²/yr depending on age, construction, and risk.
A17: Structural / Capex Reserve | B17: € per m² GLA / yr | C17: 5 | D17: =C17*B6 -> 21150 | E17: IREBS benchmark: €4–€8/m²/yr for retail. Higher for older assets.
A18: Ground Rent — Erbpachtzins | B18: € per year (if applicable) | C18: 0 | D18: =C18 -> 0 | E18: Enter 0 if freehold (Volleigentum). Fixed annual charge if leasehold.
A19: Grundsteuer — Property Tax | B19: € per year | C19: 0 | D19: =C19 -> 0 | E19: Varies by municipality (Hebesatz). Typically passed to tenants but landlord bears cost on VACANT units — enter only the non-recoverable portion.
A20: Void Service Charge (on vacant units) | B20: € per m² vacant / yr | C20: 18 | D20: =C20*B8 -> 8100 | E20: Landlord bears service charge on empty units. Typical: €15–€25/m²/yr. CRITICAL — often omitted in amateur models.
A21: Void Insurance (on vacant units) | B21: € per m² vacant / yr | C21: 1.5 | D21: =C21*B8 -> 675 | E21: Additional insurance premium on unoccupied space. Typically €1–€2/m²/yr.
A22: Letting / Re-Leasing Costs | B22: % of Annual Rent (amortised) | C22: 0.05 | D22: =C22*B5 -> 22512 | E22: Mieterausbaukostenzuschuss + agent fee amortised over avg lease term. Retail fit-out contributions: €50–€150/m².
A23: Other Non-Recoverable Costs | B23: € per year | C23: 0 | D23: =C23 -> 0 | E23: Legal, accounting, other non-recoverable items.
A25: C | NOI CALCULATION BRIDGE (referenced by Deal Overview and Python engine)
A26: Gross Passing Rent (€/yr) | B26: =B5 -> 450240
A27: Less: Total Non-Recoverable Costs | B27: =SUM(D14:D23)*-1 -> -72016.8
A28: NET OPERATING INCOME (€/yr) | B28: =B26+B27 -> 378223.2
A29: Implied NOI Margin (%) | B29: =IFERROR(B28/B5,0) -> 0.84004797
A30: NOI per m² GLA (€/yr) | B30: =IFERROR(B28/B6,0) -> 89.414468
A31: NOI per m² Leased (€/yr) | B31: =IFERROR(B28/B7,0) -> 100.05905

Sheet CPI Projections
A1: 10-YEAR CPI RENT PROJECTION | German Indexation Model
A3: ASSUMPTIONS
A4: Base Year Gross Passing Rent (€) | B4: ='Rent Roll'!B110 -> 450240
A5: CPI Assumption – Base Case (%) | B5: 0.025
A6: CPI Assumption – Bear Case (%) | B6: 0.01
A7: CPI Assumption – Bull Case (%) | B7: 0.035
A8: Average CPI Pass-Through (%) | B8: ='Rent Roll'!B118 -> 0.02020202
A9: CPI Trigger Threshold (%) | B9: 0.1
A10: Vacancy Growth Rate / yr (%) | B10: 0.005
A11: Exit Cap Rate – Base (%) | B11: 0.065
A12: Exit Cap Rate – Bear (%) | B12: 0.08
A13: Exit Cap Rate – Bull (%) | B13: 0.055
A16: Metric | B16: Year 1 | C16: Year 2 | D16: Year 3 | E16: Year 4 | F16: Year 5 | G16: Year 6 | H16: Year 7 | I16: Year 8 | J16: Year 9 | K16: Year 10
A17: CPI Index (Base=1.0) | B17: =(1+$B$5)^1 -> 1.025 | C17: =(1+$B$5)^2 -> 1.050625 | D17: =(1+$B$5)^3 -> 1.0768906 | E17: =(1+$B$5)^4 -> 1.1038129 | F17: =(1+$B$5)^5 -> 1.1314082 | G17: =(1+$B$5)^6 -> 1.1596934 | H17: =(1+$B$5)^7 -> 1.1886858 | I17: =(1+$B$5)^8 -> 1.2184029 | J17: =(1+$B$5)^9 -> 1.248863 | K17: =(1+$B$5)^10 -> 1.2800845 | L17: =(1+$B$5)^11 -> 1.3120867
A18: Rent – Base Case (€) | B18: =$B$4*(1+$B$5*$B$8)^1 -> 450467.39 | C18: =$B$4*(1+$B$5*$B$8)^2 -> 450694.9 | D18: =$B$4*(1+$B$5*$B$8)^3 -> 450922.53 | E18: =$B$4*(1+$B$5*$B$8)^4 -> 451150.27 | F18: =$B$4*(1+$B$5*$B$8)^5 -> 451378.12 | G18: =$B$4*(1+$B$5*$B$8)^6 -> 451606.09 | H18: =$B$4*(1+$B$5*$B$8)^7 -> 451834.17 | I18: =$B$4*(1+$B$5*$B$8)^8 -> 452062.37 | J18: =$B$4*(1+$B$5*$B$8)^9 -> 452290.68 | K18: =$B$4*(1+$B$5*$B$8)^10 -> 452519.11 | L18: =$B$4*(1+$B$5*$B$8)^11 -> 452747.66
A19: Rent – Bear Case (€) | B19: =$B$4*(1+$B$6*$B$8)^1 -> 450330.96 | C19: =$B$4*(1+$B$6*$B$8)^2 -> 450421.93 | D19: =$B$4*(1+$B$6*$B$8)^3 -> 450512.93 | E19: =$B$4*(1+$B$6*$B$8)^4 -> 450603.94 | F19: =$B$4*(1+$B$6*$B$8)^5 -> 450694.97 | G19: =$B$4*(1+$B$6*$B$8)^6 -> 450786.02 | H19: =$B$4*(1+$B$6*$B$8)^7 -> 450877.09 | I19: =$B$4*(1+$B$6*$B$8)^8 -> 450968.18 | J19: =$B$4*(1+$B$6*$B$8)^9 -> 451059.28 | K19: =$B$4*(1+$B$6*$B$8)^10 -> 451150.4 | L19: =$B$4*(1+$B$6*$B$8)^11 -> 451241.54
A20: Rent – Bull Case (€) | B20: =$B$4*(1+$B$7*$B$8)^1 -> 450558.35 | C20: =$B$4*(1+$B$7*$B$8)^2 -> 450876.93 | D20: =$B$4*(1+$B$7*$B$8)^3 -> 451195.73 | E20: =$B$4*(1+$B$7*$B$8)^4 -> 451514.76 | F20: =$B$4*(1+$B$7*$B$8)^5 -> 451834.01 | G20: =$B$4*(1+$B$7*$B$8)^6 -> 452153.49 | H20: =$B$4*(1+$B$7*$B$8)^7 -> 452473.19 | I20: =$B$4*(1+$B$7*$B$8)^8 -> 452793.12 | J20: =$B$4*(1+$B$7*$B$8)^9 -> 453113.28 | K20: =$B$4*(1+$B$7*$B$8)^10 -> 453433.66 | L20: =$B$4*(1+$B$7*$B$8)^11 -> 453754.27
A21: Cumulative Rent Growth – Base (%) | B21: =($B$4*(1+$B$5*$B$8)^1-$B$4)/$B$4 -> 0.00050505051 | C21: =($B$4*(1+$B$5*$B$8)^2-$B$4)/$B$4 -> 0.0010103561 | D21: =($B$4*(1+$B$5*$B$8)^3-$B$4)/$B$4 -> 0.0015159169 | E21: =($B$4*(1+$B$5*$B$8)^4-$B$4)/$B$4 -> 0.002021733 | F21: =($B$4*(1+$B$5*$B$8)^5-$B$4)/$B$4 -> 0.0025278046 | G21: =($B$4*(1+$B$5*$B$8)^6-$B$4)/$B$4 -> 0.0030341317 | H21: =($B$4*(1+$B$5*$B$8)^7-$B$4)/$B$4 -> 0.0035407146 | I21: =($B$4*(1+$B$5*$B$8)^8-$B$4)/$B$4 -> 0.0040475534 | J21: =($B$4*(1+$B$5*$B$8)^9-$B$4)/$B$4 -> 0.0045546481 | K21: =($B$4*(1+$B$5*$B$8)^10-$B$4)/$B$4 -> 0.0050619989 | L21: =($B$4*(1+$B$5*$B$8)^11-$B$4)/$B$4 -> 0.005569606
A22: Implied Exit Value – Base (€) | B22: =IFERROR($B$4*(1+$B$5*$B$8)^1/$B$10,0) -> 90093479 | C22: =IFERROR($B$4*(1+$B$5*$B$8)^2/$B$10,0) -> 90138981 | D22: =IFERROR($B$4*(1+$B$5*$B$8)^3/$B$10,0) -> 90184505 | E22: =IFERROR($B$4*(1+$B$5*$B$8)^4/$B$10,0) -> 90230053 | F22: =IFERROR($B$4*(1+$B$5*$B$8)^5/$B$10,0) -> 90275624 | G22: =IFERROR($B$4*(1+$B$5*$B$8)^6/$B$10,0) -> 90321217 | H22: =IFERROR($B$4*(1+$B$5*$B$8)^7/$B$10,0) -> 90366834 | I22: =IFERROR($B$4*(1+$B$5*$B$8)^8/$B$10,0) -> 90412474 | J22: =IFERROR($B$4*(1+$B$5*$B$8)^9/$B$10,0) -> 90458137 | K22: =IFERROR($B$4*(1+$B$5*$B$8)^10/$B$10,0) -> 90503823 | L22: =IFERROR($B$4*(1+$B$5*$B$8)^11/$B$10,0) -> 90549532
A23: Implied Exit Value – Bear (€) | B23: =IFERROR($B$4*(1+$B$6*$B$8)^1/$B$11,0) -> 6928168.6 | C23: =IFERROR($B$4*(1+$B$6*$B$8)^2/$B$11,0) -> 6929568.2 | D23: =IFERROR($B$4*(1+$B$6*$B$8)^3/$B$11,0) -> 6930968.1 | E23: =IFERROR($B$4*(1+$B$6*$B$8)^4/$B$11,0) -> 6932368.3 | F23: =IFERROR($B$4*(1+$B$6*$B$8)^5/$B$11,0) -> 6933768.8 | G23: =IFERROR($B$4*(1+$B$6*$B$8)^6/$B$11,0) -> 6935169.6 | H23: =IFERROR($B$4*(1+$B$6*$B$8)^7/$B$11,0) -> 6936570.6 | I23: =IFERROR($B$4*(1+$B$6*$B$8)^8/$B$11,0) -> 6937971.9 | J23: =IFERROR($B$4*(1+$B$6*$B$8)^9/$B$11,0) -> 6939373.5 | K23: =IFERROR($B$4*(1+$B$6*$B$8)^10/$B$11,0) -> 6940775.4 | L23: =IFERROR($B$4*(1+$B$6*$B$8)^11/$B$11,0) -> 6942177.6
A24: Implied Exit Value – Bull (€) | B24: =IFERROR($B$4*(1+$B$7*$B$8)^1/$B$12,0) -> 5631979.4 | C24: =IFERROR($B$4*(1+$B$7*$B$8)^2/$B$12,0) -> 5635961.6 | D24: =IFERROR($B$4*(1+$B$7*$B$8)^3/$B$12,0) -> 5639946.6 | E24: =IFERROR($B$4*(1+$B$7*$B$8)^4/$B$12,0) -> 5643934.5 | F24: =IFERROR($B$4*(1+$B$7*$B$8)^5/$B$12,0) -> 5647925.1 | G24: =IFERROR($B$4*(1+$B$7*$B$8)^6/$B$12,0) -> 5651918.6 | H24: =IFERROR($B$4*(1+$B$7*$B$8)^7/$B$12,0) -> 5655914.9 | I24: =IFERROR($B$4*(1+$B$7*$B$8)^8/$B$12,0) -> 5659914 | J24: =IFERROR($B$4*(1+$B$7*$B$8)^9/$B$12,0) -> 5663916 | K24: =IFERROR($B$4*(1+$B$7*$B$8)^10/$B$12,0) -> 5667920.8 | L24: =IFERROR($B$4*(1+$B$7*$B$8)^11/$B$12,0) -> 5671928.4

Sheet Instructions
A1: USER GUIDE | Institutional Retail Underwriter v1.0
A3: COLOUR CODE
A4: Blue text | B4: Hardcoded INPUT – enter your deal data here
A5: Black text | B5: Formula – calculated automatically, do not overwrite
A6: Yellow background | B6: Priority input – must not be left blank
A7: Light blue background | B7: Auto-calculated summary field
A9: WORKFLOW
A10: Step 1 | B10: Fill in 'Deal Overview' tab: Property Identity, Transaction, and Financing sections
A11: Step 2 | B11: Fill in 'Rent Roll' tab: one row per lease unit. Use 'VACANT' as Tenant Name for empty units
A12: Step 3 | B12: Check 'Deal Overview' KPI dashboard – metrics auto-populate from Rent Roll
A13: Step 4 | B13: Review 'CPI Projections' – adjust CPI and Exit Cap Rate assumptions in blue cells
A14: Step 5 | B14: Upload file into the Python underwriter engine for QA audit and full IC memo
A16: KEY METRICS EXPLAINED
A17: DSCR | B17: Debt Service Coverage Ratio – NOI divided by annual debt service. Bank minimum: 1.30x
A18: ICR | B18: Interest Coverage Ratio – NOI divided by interest only payment. Bank minimum: 1.75x
A19: WAULT | B19: Weighted Average Unexpired Lease Term – income-weighted remaining lease duration in years
A20: GIY | B20: Gross Initial Yield – passing rent divided by purchase price. Benchmark: 5.5–9% for DE retail
A21: LTV | B21: Loan-to-Value – senior loan divided by purchase price. Bank maximum: typically 60–65%
A22: NOI | B22: Net Operating Income – gross rent less non-recoverable operating costs (management fees, insurance)
A23: ERV | B23: Estimated Rental Value – market rent a vacant unit could achieve today per m²
A24: GrESt | B24: Grunderwerbsteuer – German real estate transfer tax, 3.5–6.5% depending on Bundesland
A25: AfA | B25: Absetzung für Abnutzung – tax depreciation, 2% linear on building value (excluding land)
A27: IMPORTANT WARNINGS
A28: ⚠ LTV > 65% | B28: Most German CRE lenders will decline or require mezzanine financing above 65% LTV
A29: ⚠ WAULT < 3 yrs | B29: Short WAULT = high re-letting risk. Institutional buyers typically require WAULT > 4 years
A30: ⚠ DSCR < 1.20x | B30: Below minimum bank covenant. Deal will not pass credit committee
A31: ⚠ Anchor > 60% | B31: High single-tenant concentration risk. Stress-test anchor departure scenario
A32: ⚠ Vacancy > 15% | B32: Significant vacancy signals distress or structural market problems for asset type
